Workbook

Sheet Competências
A1: Competência | B1: Check
A2: Microsoft Power BI | B2: ok
A3: Inteligência de negócios (BI) | B3: ok
A4: Suporte ao cliente | B4: ok
A5: Sucesso do cliente
A6: Inteligência artificial
A7: Previsão de receitas
A8: Previsão de demanda
A9: Análises de mercado
A10: Mapeamento de processos de negócios
A11: Gestão de riscos de terceiros
A12: Análise financeira
A13: Gestão de orçamentos
A14: Gestão logística
A15: Análise de fusões e aquisições
A16: MRP (Planejamento das necessidades de materiais)
... A86: Seis Sigma

Sheet Planilha2
A1: Competência | B1: Critério | C1: Sanofi - Operador | D1: Nycomed - Qualidade | E1: Essencis - Negócios | F1: Resinor - Qualidade | G1: Pierre - Supervisor Produção | H1: VitaLabor - Coord Produção | I1: Trifil - Proc/Sistemas | J1: Trifil - Expedição | K1: Trifil - Materiais | L1: Trifil - Inteligência Comercial | M1: Trifil - S&OP | N1: VivaReal - Gerente | O1: Renault - CS | P1: iFood - Head Ops | Q1: iFood - Diretor Ops | R1: Wehandle - Head Ops | S1: Check
A2: Revenue Growth | B2: P&L - Receita | M2: X | N2: X | O2: X | P2: X | Q2: X | S2: ok
A3: Pricing Strategy | B3: P&L - Receita | L3: X | M3: X | N3: X | P3: X | Q3: X | S3: ok
A4: Conversion Optimization | B4: P&L - Receita | N4: X | O4: X | S4: ok
A5: Customer Retention | B5: P&L - Receita | N5: X | P5: X | Q5: X | R5: X | S5: ok
A6: Marketplace Operations | B6: P&L - Receita | N6: X | P6: X | Q6: X | R6: X | S6: ok
A7: Product Operations | B7: P&L - Receita | N7: X | O7: X | P7: X | Q7: X | R7: X | S7: ok
A8: New Business Development | B8: P&L - Receita | E8: X | O8: X | Q8: X | R8: X | S8: ok
A9: Commercial Strategy | B9: P&L - Receita | L9: X | M9: X | N9: X | Q9: X | R9: X | S9: ok
A10: Cost Reduction | B10: P&L - Custo | G10: X | H10: X | I10: X | J10: X | K10: X | M10: X | N10: X | O10: X | P10: X | Q10: X | R10: X | S10: ok
A11: Operational Efficiency | B11: P&L - Custo | G11: X | H11: X | I11: X | J11: X | K11: X | L11: X | M11: X | N11: X | O11: X | P11: X | Q11: X | R11: X | S11: ok
A12: Process Optimization | B12: P&L - Custo | I12: X | J12: X | K12: X | L12: X | M12: X | N12: X | O12: X | P12: X | Q12: X | R12: X | S12: ok
A13: Budgeting & Cost Control | B13: P&L - Custo | G13: X | H13: X | I13: X | J13: X | K13: X | L13: X | M13: X | N13: X | O13: X | P13: X | Q13: X | R13: X | S13: ok
A14: Profitability Analysis | B14: P&L - Custo | E14: X | L14: X | M14: X | N14: X | O14: X | P14: X | Q14: X | R14: X | S14: ok
A15: Unit Economics | B15: P&L - Custo | L15: X | M15: X | N15: X | P15: X | Q15: X | R15: X | S15: ok
A16: Scalable Operations | B16: Escala | N16: X | O16: X | P16: X | Q16: X | R16: X | S16: ok
A17: Operations Leadership | B17: Escala | D17: X | G17: X | H17: X | I17: X | J17: X | K17: X | L17: X | M17: X | N17: X | O17: X | P17: X | Q17: X | R17: X | S17: ok
A18: Supply Chain Management | B18: Escala | G18: X | H18: X | J18: X | K18: X | M18: X | S18: ok
A19: Logistics & Last Mile | B19: Escala | P19: X | Q19: X | S19: ok
A20: S&OP | B20: Escala | M20: X | P20: X | Q20: X | R20: X | S20: ok
A21: Demand Planning | B21: Escala | H21: X | M21: X | N21: X | O21: X | P21: X | Q21: X | R21: X | S21: ok
A22: Capacity Planning | B22: Escala | G22: X | H22: X | J22: X | M22: X | N22: X | O22: X | P22: X | Q22: X | R22: X | S22: ok
A23: 3PL Management | B23: Escala | P23: X | Q23: X | S23: ok
A24: Customer Experience (CX) | B24: Experiência | N24: X | O24: X | R24: X | S24: ok
A25: Customer Success | B25: Experiência | N25: X | O25: X | R25: X | S25: ok
A26: CRM Strategy | B26: Experiência | N26: X | O26: X | R26: X | S26: ok
A27: Performance Management | B27: Experiência | L27: X | N27: X | O27: X | P27: X | Q27: X | R27: X | S27: ok
A28: KPI / OKR Management | B28: Experiência | F28: X | G28: X | H28: X | I28: X | J28: X | K28: X | L28: X | M28: X | N28: X | O28: X | P28: X | Q28: X | S28: ok
A29: Continuous Improvement | B29: Experiência | D29: X | E29: X | F29: X | G29: X | H29: X | I29: X | J29: X | K29: X | L29: X | M29: X | N29: X | O29: X | P29: X | Q29: X | R29: X | S29: ok
A30: Change Management | B30: Experiência | N30: X | O30: X | P30: X | Q30: X | R30: X | S30: ok
A31: Stakeholder Management | B31: Experiência | L31: X | M31: X | N31: X | O31: X | P31: X | Q31: X | R31: X | S31: ok
A32: Team Leadership | B32: Experiência | D32: X | G32: X | H32: X | J32: X | K32: X | L32: X | M32: X | N32: X | O32: X | S32: ok
A33: Leadership of Leaders | B33: Experiência | N33: X | O33: X | P33: X | Q33: X | R33: X | S33: ok
A34: Data-Driven Decision Making | B34: Sistema | L34: X | M34: X | N34: X | O34: X | P34: X | Q34: X | R34: X | S34: ok
A35: Structured Problem Solving | B35: Sistema | P35: X | Q35: X | R35: X | S35: ok
A36: Business Intelligence | B36: Sistema | L36: X | M36: X | N36: X | O36: X | P36: X | Q36: X | R36: X | S36: ok
A37: Advanced Analytics | B37: Sistema | M37: X | N37: X | O37: X | P37: X | Q37: X | R37: X | S37: ok
A38: Process Automation | B38: Sistema | N38: X | O38: X | P38: X | Q38: X | R38: X | S38: ok
A39: Data Architecture | B39: Sistema
A40: Tech-enabled Operations | B40: Sistema | N40: X | P40: X | Q40: X | R40: X | S40: ok
...

Sheet Planilha1
A1: Experience | B1: Competency 1 | C1: Competency 2 | D1: Competency 3 | E1: Competency 4 | F1: Competency 5
A2: Sanofi - Operator | B2: Quality Management | C2: Process Optimization | Continuous Improvement | D2: Operational Efficiency
A3: Nycomed - Quality | B3: Quality Management | Risk Management | C3: Process Optimization | D3: Continuous Improvement
A4: Essencis - Business Analyst | B4: M&A | C4: Financial Modeling | Profitability Analysis | D4: Strategic Planning
A5: Resinor - Quality Coordinator | B5: Quality Management | C5: Continuous Improvement | Process Optimization | D5: Stakeholder Management
A6: Pierre - Production Supervisor | B6: Team Leadership | C6: Operational Efficiency | D6: Process Optimization | E6: ERP Implementation | F6: Inventory Management
A7: VitaLabor - Production Coordinator | B7: Operational Efficiency | C7: Process Automation | D7: Capacity Planning | E7: Cost Reduction | F7: Supply Chain Management
A8: Trifil - Process & Systems | B8: Process Optimization | Continuous Improvement | C8: Cost Reduction | D8: Operational Efficiency | E8: KPI / OKR Management
A9: Trifil - Logistics | B9: Logistics & Last Mile | C9: Supply Chain Management | D9: Operational Efficiency | Process Optimization
A10: Trifil - Materials | B10: Supply Chain Management | C10: Cost Reduction | D10: Inventory Optimization | Demand Planning
A11: Trifil - Commercial Intelligence | B11: Revenue Growth | C11: Pricing Strategy | D11: Business Intelligence | Data-Driven Decision Making | E11: Conversion Optimization
A12: Trifil - S&OP | B12: S&OP | C12: Demand Planning | Capacity Planning | D12: Cost Reduction | E12: Data-Driven Decision Making
A13: VivaReal - Manager | B13: Customer Experience (CX) | Customer Success | C13: Conversion Optimization | D13: CRM Strategy | E13: Marketplace Operations
A14: Renault - Customer Success Manager | B14: Conversion Optimization | C14: Customer Success | D14: Data-Driven Decision Making | Process Optimization
A15: iFood - Head of Operations | B15: Data-Driven Decision Making | C15: Scalable Operations | D15: Process Automation | E15: Operational Efficiency | F15: Structured Problem Solving
A16: iFood - Director of Operations | B16: Operations Leadership | C16: Scalable Operations | D16: Cost Reduction | Profitability Analysis | E16: Strategic Planning
A17: Wehandle - Head of Operations | B17: Process Automation | C17: Customer Retention | D17: Operational Efficiency | E17: Data-Driven Decision Making | F17: Customer Experience (CX) | Tech-enabled Operations

Sheet refin_2
A1: Olhar se faz sentido
A2: Experiência | B2: Competência 1 | C2: Competência 2 | D2: Competência 3 | E2: Competência 4 | F2: Competência 5
A3: Sanofi - Operador | B3: Quality Management | C3: Process Discipline (GMP) | D3: Operational Execution
A4: Nycomed - Qualidade | B4: Quality Assurance | C4: Process Validation | D4: Risk Management
A5: Essencis - Negócios | B5: M&A Analysis | C5: Financial Modeling | D5: Investment Analysis (NPV) | E5: Strategic Evaluation
A6: Resinor - Qualidade | B6: Quality Systems Leadership | C6: Process Standardization | D6: Audit & Compliance | E6: Continuous Improvement
A7: Pierre - Supervisor Produção | B7: Team Leadership | C7: Production Planning | D7: Inventory Management | E7: ERP Implementation | F7: Productivity Improvement
A8: VitaLabor - Coord Produção | B8: End-to-End Operations | C8: Process Automation | D8: Capacity Expansion | E8: Supply Planning | F8: Operational Turnaround
A9: Trifil - Proc/Sistemas | B9: Process Optimization | C9: Cost Reduction | D9: Industrial Automation | E9: KPI Management | F9: Operational Efficiency
A10: Trifil - Expedição | B10: Logistics Operations | C10: Warehouse Optimization | D10: ERP Deployment | E10: Supply Chain Execution
A11: Trifil - Materiais | B11: Strategic Sourcing | C11: Cost Optimization | D11: Inventory Turnover | E11: Supplier Management
A12: Trifil - Inteligência Comercial | B12: Revenue Growth | C12: Pricing Strategy | D12: Business Intelligence | E12: Commercial Analytics | F12: Decision Support Systems
A13: Trifil - S&OP | B13: S&OP Leadership | C13: Demand Planning | D13: Integrated Planning | E13: Cost Management | F13: Scenario Simulation
A14: VivaReal - Gerente | B14: Customer Experience (CX) | C14: Customer Success | D14: Conversion Optimization | E14: CRM Strategy | F14: Marketplace Operations
A15: Renault - CS | B15: Sales Conversion | C15: Lead Management | D15: Digital Funnel Optimization | E15: Operational Restructuring
A16: iFood - Head Ops | B16: Data-Driven Decision Making | C16: Real-Time Operations | D16: Fleet Optimization | E16: Operational Scalability | F16: Simulation Modeling
A17: iFood - Diretor Ops | B17: Operations Leadership | C17: Scalable Operations | D17: Unit Economics | E17: Platform Expansion | F17: P&L Management
A18: Wehandle - Head Ops | B18: AI-Driven Operations | C18: Process Automation | D18: Cost Efficiency | E18: Customer Retention | F18: Tech-enabled CX

Sheet refin_1
A1: Experience | B1: Competency 1 | C1: Competency 2 | D1: Competency 3 | E1: Competency 4 | F1: Competency 5
A2: Sanofi - Operator | B2: Quality Management | C2: GMP Compliance | D2: Process Discipline
A3: Nycomed - Quality | B3: Process Validation | C3: Quality Assurance | D3: Stability Analysis
A4: Essencis - Business Analyst | B4: M&A | C4: Financial Modeling | D4: Investment Analysis (NPV) | E4: Strategic Evaluation
A5: Resinor - Quality Coordinator | B5: Quality Systems Leadership | C5: Audit & Compliance | D5: Metrology & Calibration | E5: Documentation Control
A6: Pierre - Production Supervisor | B6: Team Leadership | C6: Production Planning | D6: Inventory Management | E6: ERP Implementation | F6: Productivity Improvement
A7: VitaLabor - Production Coordinator | B7: End-to-End Operations | C7: Process Automation | D7: Capacity Expansion | E7: Supply Planning | F7: Operational Turnaround
A8: Trifil - Process & Systems | B8: Process Optimization | C8: Industrial Automation | D8: KPI Management | E8: Operational Efficiency | F8: PDCA Implementation
A9: Trifil - Logistics | B9: Logistics Operations | C9: Warehouse Optimization | D9: Picking Automation | E9: Distribution Planning
A10: Trifil - Materials | B10: Strategic Sourcing | C10: Cost Optimization | D10: Inventory Turnover | E10: Supplier Negotiation
A11: Trifil - Commercial Intelligence | B11: Revenue Growth | C11: Pricing Strategy | D11: Commercial Analytics | E11: Sales Intelligence | F11: Margin Optimization
A12: Trifil - S&OP | B12: S&OP Leadership | C12: Demand Planning | D12: Scenario Simulation | E12: Integrated Planning | F12: GGF Cost Reduction
A13: VivaReal - Manager | B13: Customer Experience (CX) | C13: Customer Success | D13: Conversion Optimization | E13: CRM Strategy | F13: Marketplace Operations
A14: Renault - Customer Success Manager | B14: Sales Conversion | C14: Lead Qualification | D14: Funnel Optimization | E14: BPO Insourcing
A15: iFood - Head of Operations | B15: Data-Driven Decision Making | C15: Real-Time Operations | D15: Fleet Optimization | E15: Simulation Modeling | F15: Operational Scalability
A16: iFood - Director of Operations | B16: Operations Leadership | C16: Scalable Operations | D16: Unit Economics | E16: Platform Expansion | F16: P&L Management
A17: Wehandle - Head of Operations | B17: AI-Driven Operations | C17: Customer Retention | D17: Cost Efficiency | E17: Tech-enabled CX | F17: Automation Strategy

Sheet Planilha5
A1: lista MECE | B1: Na lista
A2: AI-Driven Operations | B2: =_xlfn.XLOOKUP(A2,Planilha2!A:A,A:A,"")
A3: Audit & Compliance | B3: =_xlfn.XLOOKUP(A3,Planilha2!A:A,A:A,"")
A4: Automation Strategy | B4: =_xlfn.XLOOKUP(A4,Planilha2!A:A,A:A,"")
A5: BPO Insourcing | B5: =_xlfn.XLOOKUP(A5,Planilha2!A:A,A:A,"")
A6: Business Intelligence | B6: =_xlfn.XLOOKUP(A6,Planilha2!A:A,A:A,"") -> Inventory Turnover
A7: Capacity Expansion | B7: =_xlfn.XLOOKUP(A7,Planilha2!A:A,A:A,"")
A8: Commercial Analytics | B8: =_xlfn.XLOOKUP(A8,Planilha2!A:A,A:A,"")
A9: Continuous Improvement | B9: =_xlfn.XLOOKUP(A9,Planilha2!A:A,A:A,"") -> Fleet Optimization
A10: Conversion Optimization | B10: =_xlfn.XLOOKUP(A10,Planilha2!A:A,A:A,"") -> Automation Strategy
A11: Cost Efficiency | B11: =_xlfn.XLOOKUP(A11,Planilha2!A:A,A:A,"")
A12: Cost Management | B12: =_xlfn.XLOOKUP(A12,Planilha2!A:A,A:A,"")
A13: Cost Optimization | B13: =_xlfn.XLOOKUP(A13,Planilha2!A:A,A:A,"")
... A88: Warehouse Optimization | B88: =_xlfn.XLOOKUP(A88,Planilha2!A:A,A:A,"")

Sheet refinamento
A1: lista MECE
A2: AI-Driven Operations
A3: Audit & Compliance
A4: Automation Strategy
A5: BPO Insourcing
A6: Capacity Expansion
A7: Commercial Analytics
A8: Cost Efficiency
A9: Cost Management
A10: Cost Optimization
A11: Decision Support Systems
A12: Digital Funnel Optimization
... A64: Warehouse Optimization
